{
    "docs": "https://docs.ansible.com/ansible/2.10/dev_guide/testing/sanity/compile.html", 
    "results": [
        {
            "message": "The test `ansible-test sanity --test compile --python 2.6` [[explain](https://docs.ansible.com/ansible/2.10/dev_guide/testing/sanity/compile.html)] failed with 382 errors:", 
            "output": ".venv/lib/python3.8/site-packages/_pytest/_argcomplete.py:76:35: SyntaxError: def __init__(self, directories: bool = True) -> None:\n.venv/lib/python3.8/site-packages/_pytest/_code/code.py:58:33: SyntaxError: def __init__(self, rawcode) -> None:\n.venv/lib/python3.8/site-packages/_pytest/_code/source.py:23:27: SyntaxError: def __init__(self, obj: object = None) -> None:\n.venv/lib/python3.8/site-packages/_pytest/_io/saferepr.py:9:25: SyntaxError: def _try_repr_or_str(obj: object) -> str:\n.venv/lib/python3.8/site-packages/_pytest/_io/terminalwriter.py:16:26: SyntaxError: def get_terminal_width() -> int:\n.venv/lib/python3.8/site-packages/_pytest/_io/wcwidth.py:6:14: SyntaxError: def wcwidth(c: str) -> int:\n.venv/lib/python3.8/site-packages/_pytest/assertion/__init__.py:22:28: SyntaxError: def pytest_addoption(parser: Parser) -> None:\n.venv/lib/python3.8/site-packages/_pytest/assertion/rewrite.py:60:30: SyntaxError: def __init__(self, config: Config) -> None:\n.venv/lib/python3.8/site-packages/_pytest/assertion/truncate.py:19:16: SyntaxError: explanation: List[str], item: Item, max_length: Optional[int] = None\n.venv/lib/python3.8/site-packages/_pytest/assertion/util.py:32:35: SyntaxError: def format_explanation(explanation: str) -> str:\n.venv/lib/python3.8/site-packages/_pytest/cacheprovider.py:68:31: SyntaxError: def for_config(cls, config: Config) -> \"Cache\":\n.venv/lib/python3.8/site-packages/_pytest/capture.py:34:28: SyntaxError: def pytest_addoption(parser: Parser) -> None:\n.venv/lib/python3.8/site-packages/_pytest/compat.py:60:22: SyntaxError: def _format_args(func: Callable[..., Any]) -> str:\n.venv/lib/python3.8/site-packages/_pytest/config/__init__.py:106:13: SyntaxError: path: py.path.local,\n.venv/lib/python3.8/site-packages/_pytest/config/argparsing.py:42:14: SyntaxError: usage: Optional[str] = None,\n.venv/lib/python3.8/site-packages/_pytest/config/findpaths.py:23:27: SyntaxError: def _parse_ini_config(path: Path) -> iniconfig.IniConfig:\n.venv/lib/python3.8/site-packages/_pytest/debugging.py:33:31: SyntaxError: def _validate_usepdb_cls(value: str) -> Tuple[str, str]:\n.venv/lib/python3.8/site-packages/_pytest/deprecated.py:17:22: SyntaxError: \"pytest_catchlog\",\n.venv/lib/python3.8/site-packages/_pytest/doctest.py:65:28: SyntaxError: def pytest_addoption(parser: Parser) -> None:\n.venv/lib/python3.8/site-packages/_pytest/faulthandler.py:17:28: SyntaxError: def pytest_addoption(parser: Parser) -> None:\n.venv/lib/python3.8/site-packages/_pytest/fixtures.py:105:32: SyntaxError: def pytest_sessionstart(session: \"Session\") -> None:\n.venv/lib/python3.8/site-packages/_pytest/freeze_support.py:9:23: SyntaxError: def freeze_includes() -> List[str]:\n.venv/lib/python3.8/site-packages/_pytest/helpconfig.py:46:28: SyntaxError: def pytest_addoption(parser: Parser) -> None:\n.venv/lib/python3.8/site-packages/_pytest/hookspec.py:54:34: SyntaxError: def pytest_addhooks(pluginmanager: \"PytestPluginManager\") -> None:\n.venv/lib/python3.8/site-packages/_pytest/junitxml.py:40:23: SyntaxError: def bin_xml_escape(arg: object) -> str:\n.venv/lib/python3.8/site-packages/_pytest/logging.py:42:39: SyntaxError: def _remove_ansi_escape_sequences(text: str) -> str:\n.venv/lib/python3.8/site-packages/_pytest/main.py:51:28: SyntaxError: def pytest_addoption(parser: Parser) -> None:\n.venv/lib/python3.8/site-packages/_pytest/mark/__init__.py:48:12: SyntaxError: *values: object,\n.venv/lib/python3.8/site-packages/_pytest/mark/expression.py:65:30: SyntaxError: def __init__(self, column: int, message: str) -> None:\n.venv/lib/python3.8/site-packages/_pytest/mark/structures.py:41:22: SyntaxError: def istestfunc(func) -> bool:\n.venv/lib/python3.8/site-packages/_pytest/monkeypatch.py:30:19: SyntaxError: def monkeypatch() -> Generator[\"MonkeyPatch\", None, None]:\n.venv/lib/python3.8/site-packages/_pytest/nodes.py:53:22: SyntaxError: def _splitnode(nodeid: str) -> Tuple[str, ...]:\n.venv/lib/python3.8/site-packages/_pytest/nose.py:24:31: SyntaxError: def is_potential_nosetest(item: Item) -> bool:\n.venv/lib/python3.8/site-packages/_pytest/outcomes.py:29:27: SyntaxError: def __init__(self, msg: Optional[str] = None, pytrace: bool = True) -> None:\n.venv/lib/python3.8/site-packages/_pytest/pastebin.py:18:28: SyntaxError: def pytest_addoption(parser: Parser) -> None:\n.venv/lib/python3.8/site-packages/_pytest/pathlib.py:47:23: SyntaxError: def get_lock_path(path: _AnyPurePath) -> _AnyPurePath:\n.venv/lib/python3.8/site-packages/_pytest/pytester.py:63:28: SyntaxError: def pytest_addoption(parser: Parser) -> None:\n.venv/lib/python3.8/site-packages/_pytest/python.py:81:28: SyntaxError: def pytest_addoption(parser: Parser) -> None:\n.venv/lib/python3.8/site-packages/_pytest/python_api.py:30:38: SyntaxError: def _non_numeric_type_error(value, at: Optional[str]) -> TypeError:\n.venv/lib/python3.8/site-packages/_pytest/recwarn.py:30:15: SyntaxError: def recwarn() -> Generator[\"WarningsRecorder\", None, None]:\n.venv/lib/python3.8/site-packages/_pytest/reports.py:69:28: SyntaxError: def __init__(self, **kw: Any) -> None:\n.venv/lib/python3.8/site-packages/_pytest/runner.py:46:28: SyntaxError: def pytest_addoption(parser: Parser) -> None:\n.venv/lib/python3.8/site-packages/_pytest/setuponly.py:14:28: SyntaxError: def pytest_addoption(parser: Parser) -> None:\n.venv/lib/python3.8/site-packages/_pytest/setupplan.py:12:28: SyntaxError: def pytest_addoption(parser: Parser) -> None:\n.venv/lib/python3.8/site-packages/_pytest/skipping.py:29:28: SyntaxError: def pytest_addoption(parser: Parser) -> None:\n.venv/lib/python3.8/site-packages/_pytest/stepwise.py:12:28: SyntaxError: def pytest_addoption(parser: Parser) -> None:\n.venv/lib/python3.8/site-packages/_pytest/store.py:85:24: SyntaxError: def __init__(self) -> None:\n.venv/lib/python3.8/site-packages/_pytest/terminal.py:82:23: SyntaxError: option_strings: Sequence[str],\n.venv/lib/python3.8/site-packages/_pytest/tmpdir.py:44:32: SyntaxError: def from_config(cls, config: Config) -> \"TempPathFactory\":\n.venv/lib/python3.8/site-packages/_pytest/unittest.py:47:14: SyntaxError: collector: PyCollector, name: str, obj: object\n.venv/lib/python3.8/site-packages/_pytest/warning_types.py:66:28: SyntaxError: def simple(cls, apiname: str) -> \"PytestExperimentalApiWarning\":\n.venv/lib/python3.8/site-packages/_pytest/warnings.py:20:28: SyntaxError: def pytest_configure(config: Config) -> None:\n.venv/lib/python3.8/site-packages/ansible/galaxy/collection.py:1119:44: SyntaxError: with open(b_path, 'wb') as file_obj, BytesIO(b) as b_io:\n.venv/lib/python3.8/site-packages/ansible_collections/arista/eos/plugins/module_utils/network/eos/config/ospf_interfaces/ospf_interfaces.py:95:41: SyntaxError: wantd = {entry[\"name\"]: entry for entry in self.want}\n.venv/lib/python3.8/site-packages/ansible_collections/arista/eos/plugins/module_utils/network/eos/config/ospfv3/ospfv3.py:102:35: SyntaxError: entry[\"vrf\"]: entry for entry in self.want.get(\"processes\", [])\n.venv/lib/python3.8/site-packages/ansible_collections/cisco/asa/plugins/module_utils/network/asa/config/acls/acls.py:67:47: SyntaxError: wantd = {(entry[\"name\"]): entry for entry in self.want[\"acls\"]}\n.venv/lib/python3.8/site-packages/ansible_collections/cisco/asa/plugins/module_utils/network/asa/config/ogs/ogs.py:67:54: SyntaxError: wantd = {(entry[\"object_type\"]): entry for entry in self.want}\n.venv/lib/python3.8/site-packages/ansible_collections/cisco/ios/plugins/module_utils/network/ios/config/ospf_interfaces/ospf_interfaces.py:69:47: SyntaxError: wantd = {(entry[\"name\"]): entry for entry in self.want}\n.venv/lib/python3.8/site-packages/ansible_collections/cisco/ios/plugins/module_utils/network/ios/config/ospfv2/ospfv2.py:70:19: SyntaxError: for entry in self.want.get(\"processes\", [])\n.venv/lib/python3.8/site-packages/ansible_collections/cisco/ios/plugins/module_utils/network/ios/config/ospfv3/ospfv3.py:70:19: SyntaxError: for entry in self.want.get(\"processes\", [])\n.venv/lib/python3.8/site-packages/ansible_collections/cisco/ios/plugins/module_utils/network/ios/facts/ospfv3/ospfv3.py:56:32: SyntaxError: k: v for k, v in iteritems(capdict) if v is not None\n.venv/lib/python3.8/site-packages/ansible_collections/cisco/iosxr/plugins/module_utils/network/iosxr/config/acl_interfaces/acl_interfaces.py:66:41: SyntaxError: wantd = {entry[\"name\"]: entry for entry in self.want}\n.venv/lib/python3.8/site-packages/ansible_collections/cisco/iosxr/plugins/module_utils/network/iosxr/config/ospf_interfaces/ospf_interfaces.py:102:41: SyntaxError: wantd = {entry[\"name\"]: entry for entry in self.want}\n.venv/lib/python3.8/site-packages/ansible_collections/cisco/iosxr/plugins/module_utils/network/iosxr/config/ospfv2/ospfv2.py:71:19: SyntaxError: for entry in self.want.get(\"processes\", [])\n.venv/lib/python3.8/site-packages/ansible_collections/cisco/iosxr/plugins/module_utils/network/iosxr/config/ospfv3/ospfv3.py:66:19: SyntaxError: for entry in self.want.get(\"processes\", [])\n.venv/lib/python3.8/site-packages/ansible_collections/cisco/nxos/plugins/module_utils/network/nxos/config/ospf_interfaces/ospf_interfaces.py:82:41: SyntaxError: wantd = {entry[\"name\"]: entry for entry in self.want}\n.venv/lib/python3.8/site-packages/ansible_collections/cisco/nxos/plugins/module_utils/network/nxos/config/ospfv2/ospfv2.py:98:15: SyntaxError: for entry in self.want.get(\"processes\", [])\n.venv/lib/python3.8/site-packages/ansible_collections/cisco/nxos/plugins/module_utils/network/nxos/config/ospfv3/ospfv3.py:88:15: SyntaxError: for entry in self.want.get(\"processes\", [])\n.venv/lib/python3.8/site-packages/ansible_collections/containers/podman/plugins/modules/podman_container.py:1317:23: SyntaxError: 'env_file',  # We can't get env vars from file to check\n.venv/lib/python3.8/site-packages/ansible_collections/infinidat/infinibox/plugins/modules/infini_port.py:145:35: SyntaxError: trimmed_item = {key:val for key, val in init.items() if key in include_key_list}\n.venv/lib/python3.8/site-packages/ansible_collections/netbox/netbox/docs/conf.py:87:140: SyntaxError: args_string = f\"junk plugin --dest-dir plugins/{plugin_type}/{file_name}/ --plugin-type {plugin_type} netbox.netbox.{file_name}\"\n.venv/lib/python3.8/site-packages/ansible_collections/netbox/netbox/plugins/inventory/nb_inventory.py:1169:55: SyntaxError: self.devices_lookup = {device[\"id\"]: device for device in self.devices_list}\n.venv/lib/python3.8/site-packages/ansible_collections/netbox/netbox/plugins/module_utils/netbox_utils.py:396:20: SyntaxError: \"circuit_types\",\n.venv/lib/python3.8/site-packages/ansible_collections/netbox/netbox/tests/test_data.py:14:55: SyntaxError: with open(f\"{path}/test_data/{test_path}/data.json\", \"r\") as f:\n.venv/lib/python3.8/site-packages/ansible_collections/theforeman/foreman/plugins/module_utils/_apypie.py:142:41: SyntaxError: required_params = {param.name for param in params if param.required}\n.venv/lib/python3.8/site-packages/ansible_collections/theforeman/foreman/plugins/module_utils/foreman_helper.py:56:34: SyntaxError: parameter_ansible_spec = {k: v for (k, v) in parameter_foreman_spec.items() if k != 'id'}\n.venv/lib/python3.8/site-packages/ansible_collections/theforeman/foreman/plugins/modules/activation_key.py:322:23: SyntaxError: for product in product_content['results']\n.venv/lib/python3.8/site-packages/ansible_collections/theforeman/foreman/plugins/modules/compute_resource.py:388:39: SyntaxError: provider_params = {k: v for k, v in module.foreman_params.pop('provider_params', dict()).items() if v is not None}\n.venv/lib/python3.8/site-packages/ansible_collections/theforeman/foreman/plugins/modules/content_view_version.py:146:52: SyntaxError: current_environment_ids = {environment['id'] for environment in content_view_version['environments']}\n.venv/lib/python3.8/site-packages/ansible_collections/theforeman/foreman/plugins/modules/installation_medium.py:123:65: SyntaxError: further_params = set(module_params.keys()) - {'name', 'entity'}\n.venv/lib/python3.8/site-packages/ansible_collections/theforeman/foreman/plugins/modules/job_template.py:410:73: SyntaxError: further_params = set(module.foreman_params.keys()) - {'name', 'entity'}\n.venv/lib/python3.8/site-packages/ansible_collections/theforeman/foreman/plugins/modules/partition_table.py:271:73: SyntaxError: further_params = set(module.foreman_params.keys()) - {'name', 'entity'}\n.venv/lib/python3.8/site-packages/ansible_collections/theforeman/foreman/plugins/modules/provisioning_template.py:312:73: SyntaxError: further_params = set(module.foreman_params.keys()) - {'name', 'entity'}\n.venv/lib/python3.8/site-packages/ansible_collections/theforeman/foreman/plugins/modules/repository_set.py:271:29: SyntaxError: repositories = [{k: v for (k, v) in sub.items() if v is not None} for sub in module.foreman_params.get('repositories', [])]\n.venv/lib/python3.8/site-packages/ansible_collections/theforeman/foreman/plugins/modules/smart_class_parameter.py:187:86: SyntaxError: current_override_values = {override_value['match']: override_value for override_value in entity.get('override_values', [])}\n.venv/lib/python3.8/site-packages/ansible_collections/vyos/vyos/plugins/module_utils/network/vyos/config/ospf_interfaces/ospf_interfaces.py:79:41: SyntaxError: wantd = {entry[\"name\"]: entry for entry in self.want}\n.venv/lib/python3.8/site-packages/asgiref/compatibility.py:32:13: SyntaxError: async def new_application(scope, receive, send):\n.venv/lib/python3.8/site-packages/asgiref/server.py:66:13: SyntaxError: async def handle(self):\n.venv/lib/python3.8/site-packages/asgiref/sync.py:191:13: SyntaxError: async def main_wrap(\n.venv/lib/python3.8/site-packages/asgiref/testing.py:23:13: SyntaxError: async def wait(self, timeout=1):\n.venv/lib/python3.8/site-packages/asgiref/timeout.py:34:16: SyntaxError: timeout: Optional[float],\n.venv/lib/python3.8/site-packages/asgiref/wsgi.py:15:13: SyntaxError: async def __call__(self, scope, receive, send):\n.venv/lib/python3.8/site-packages/attr/_make.py:448:15: SyntaxError: for name, attr in cd.items()\n.venv/lib/python3.8/site-packages/attr/_next_gen.py:18:6: SyntaxError: *,\n.venv/lib/python3.8/site-packages/cachecontrol/adapter.py:13:34: SyntaxError: invalidating_methods = {\"PUT\", \"DELETE\"}\n.venv/lib/python3.8/site-packages/cachecontrol/heuristics.py:101:12: SyntaxError: 200, 203, 204, 206, 300, 301, 404, 405, 410, 414, 501\n.venv/lib/python3.8/site-packages/cryptography/hazmat/backends/openssl/backend.py:193:23: SyntaxError: b\"aes-128-ccm\",\n.venv/lib/python3.8/site-packages/cryptography/hazmat/backends/openssl/decode_asn1.py:69:41: SyntaxError: attributes.append({attribute})\n.venv/lib/python3.8/site-packages/cryptography/x509/extensions.py:974:43: SyntaxError: _TLS_FEATURE_TYPE_TO_ENUM = {x.value: x for x in TLSFeatureType}\n.venv/lib/python3.8/site-packages/cryptography/x509/name.py:29:36: SyntaxError: _ASN1_TYPE_TO_ENUM = {i.value: i for i in _ASN1Type}\n.venv/lib/python3.8/site-packages/cryptography/x509/ocsp.py:45:42: SyntaxError: _RESPONSE_STATUS_TO_ENUM = {x.value: x for x in OCSPResponseStatus}\n.venv/lib/python3.8/site-packages/cs/_async.py:16:13: SyntaxError: async def _request(self, command, json=True, opcode_name='command',\n.venv/lib/python3.8/site-packages/cs/client.py:55:35: SyntaxError: REQUIRED_CONFIG_KEYS = {\"endpoint\", \"key\", \"secret\", \"method\", \"timeout\"}\n.venv/lib/python3.8/site-packages/django/apps/registry.py:312:40: SyntaxError: installed = {app_config.name for app_config in self.get_app_configs()}\n.venv/lib/python3.8/site-packages/django/conf/__init__.py:267:25: SyntaxError: s for s in [*self.__dict__, *dir(self.default_settings)]\n.venv/lib/python3.8/site-packages/django/conf/urls/i18n.py:8:48: SyntaxError: def i18n_patterns(*urls, prefix_default_language=True):\n.venv/lib/python3.8/site-packages/django/contrib/admin/actions.py:55:10: SyntaxError: **modeladmin.admin_site.each_context(request),\n.venv/lib/python3.8/site-packages/django/contrib/admin/checks.py:144:13: SyntaxError: *self._check_autocomplete_fields(admin_obj),\n.venv/lib/python3.8/site-packages/django/contrib/admin/decorators.py:1:26: SyntaxError: def register(*models, site=None):\n.venv/lib/python3.8/site-packages/django/contrib/admin/filters.py:308:36: SyntaxError: self.date_params = {k: v for k, v in params.items() if k.startswith(self.field_generic)}\n.venv/lib/python3.8/site-packages/django/contrib/admin/forms.py:11:10: SyntaxError: **AuthenticationForm.error_messages,\n.venv/lib/python3.8/site-packages/django/contrib/admin/options.py:98:31: SyntaxError: class BaseModelAdmin(metaclass=forms.MediaDefiningClass):\n.venv/lib/python3.8/site-packages/django/contrib/admin/sites.py:327:32: SyntaxError: 'extra_context': {**self.each_context(request), **(extra_context or {})},\n.venv/lib/python3.8/site-packages/django/contrib/admin/templatetags/admin_list.py:72:21: SyntaxError: *range(0, ON_ENDS), DOT,\n.venv/lib/python3.8/site-packages/django/contrib/admin/utils.py:18:31: SyntaxError: QUOTE_MAP = {i: '_%02X' % i for i in b'\":/_#?;@&=+$,\"[]<>%\\n\\\\'}\n.venv/lib/python3.8/site-packages/django/contrib/admin/views/main.py:180:59: SyntaxError: raise IncorrectLookupParameters(e) from e\n.venv/lib/python3.8/site-packages/django/contrib/admin/widgets.py:57:56: SyntaxError: attrs = {'class': 'vDateField', 'size': '10', **(attrs or {})}\n.venv/lib/python3.8/site-packages/django/contrib/admindocs/views.py:47:14: SyntaxError: **kwargs,\n.venv/lib/python3.8/site-packages/django/contrib/auth/admin.py:179:14: SyntaxError: **self.admin_site.each_context(request),\n.venv/lib/python3.8/site-packages/django/contrib/auth/backends.py:23:13: SyntaxError: *self.get_user_permissions(user_obj, obj=obj),\n.venv/lib/python3.8/site-packages/django/contrib/auth/forms.py:76:14: SyntaxError: **super().widget_attrs(widget),\n.venv/lib/python3.8/site-packages/django/contrib/auth/hashers.py:100:40: SyntaxError: return {hasher.algorithm: hasher for hasher in get_hashers()}\n.venv/lib/python3.8/site-packages/django/contrib/auth/management/__init__.py:18:13: SyntaxError: return [*_get_builtin_permissions(opts), *opts.permissions]\n.venv/lib/python3.8/site-packages/django/contrib/auth/migrations/0001_initial.py:29:65: SyntaxError: 'unique_together': {('content_type', 'codename')},\n.venv/lib/python3.8/site-packages/django/contrib/auth/password_validation.py:175:47: SyntaxError: self.passwords = {x.strip() for x in f}\n.venv/lib/python3.8/site-packages/django/contrib/auth/views.py:37:40: SyntaxError: return {self.request.get_host(), *self.success_url_allowed_hosts}\n.venv/lib/python3.8/site-packages/django/contrib/contenttypes/admin.py:95:20: SyntaxError: exclude = [*(self.exclude or []), *self.get_readonly_fields(request, obj)]\n.venv/lib/python3.8/site-packages/django/contrib/contenttypes/fields.py:78:13: SyntaxError: *self._check_field_name(),\n.venv/lib/python3.8/site-packages/django/contrib/contenttypes/forms.py:72:16: SyntaxError: exclude = [*(exclude or []), ct_field.name, fk_field.name]\n.venv/lib/python3.8/site-packages/django/contrib/contenttypes/management/__init__.py:28:71: SyntaxError: content_type.save(using=db, update_fields={'model'})\n.venv/lib/python3.8/site-packages/django/contrib/contenttypes/management/commands/remove_stale_contenttypes.py:58:43: SyntaxError: if objs != {ct}:\n.venv/lib/python3.8/site-packages/django/contrib/contenttypes/migrations/0001_initial.py:32:52: SyntaxError: unique_together={('app_label', 'model')},\n.venv/lib/python3.8/site-packages/django/contrib/contenttypes/models.py:62:57: SyntaxError: def get_for_models(self, *models, for_concrete_models=True):\n.venv/lib/python3.8/site-packages/django/contrib/gis/db/backends/base/operations.py:41:15: SyntaxError: 'Area', 'AsGeoJSON', 'AsGML', 'AsKML', 'AsSVG', 'Azimuth',\n.venv/lib/python3.8/site-packages/django/contrib/gis/db/backends/mysql/operations.py:59:20: SyntaxError: 'AsGML', 'AsKML', 'AsSVG', 'Azimuth', 'BoundingCircle',\n.venv/lib/python3.8/site-packages/django/contrib/gis/db/backends/oracle/introspection.py:14:14: SyntaxError: **super().data_types_reverse,\n.venv/lib/python3.8/site-packages/django/contrib/gis/db/backends/oracle/operations.py:112:16: SyntaxError: 'AsKML', 'AsSVG', 'Azimuth', 'ForcePolygonCW', 'GeoHash',\n.venv/lib/python3.8/site-packages/django/contrib/gis/db/backends/spatialite/introspection.py:13:10: SyntaxError: **FlexibleFieldLookupDict.base_data_types_reverse,\n.venv/lib/python3.8/site-packages/django/contrib/gis/db/backends/spatialite/operations.py:83:40: SyntaxError: unsupported = {'BoundingCircle', 'GeometryDistance', 'MemSize'}\n.venv/lib/python3.8/site-packages/django/contrib/gis/db/models/aggregates.py:34:17: SyntaxError: *self.get_source_expressions(),\n.venv/lib/python3.8/site-packages/django/contrib/gis/db/models/fields.py:207:68: SyntaxError: def __init__(self, verbose_name=None, dim=2, geography=False, *, extent=(-180.0, -90.0, 180.0, 90.0),\n.venv/lib/python3.8/site-packages/django/contrib/gis/db/models/functions.py:120:39: SyntaxError: clone.set_source_expressions([*self.get_source_expressions(), tolerance])\n.venv/lib/python3.8/site-packages/django/contrib/gis/db/models/lookups.py:22:14: SyntaxError: rhs, *self.rhs_params = rhs if isinstance(rhs, (list, tuple)) else [rhs]\n.venv/lib/python3.8/site-packages/django/contrib/gis/forms/fields.py:27:25: SyntaxError: def __init__(self, *, srid=None, geom_type=None, **kwargs):\n.venv/lib/python3.8/site-packages/django/contrib/gis/forms/widgets.py:71:14: SyntaxError: **(attrs or {}),\n.venv/lib/python3.8/site-packages/django/contrib/gis/gdal/field.py:232:30: SyntaxError: ROGRFieldTypes = {cls: num for num, cls in OGRFieldTypes.items()}\n.venv/lib/python3.8/site-packages/django/contrib/gis/gdal/geomtype.py:31:34: SyntaxError: _str_types = {v.lower(): k for k, v in _types.items()}\n.venv/lib/python3.8/site-packages/django/contrib/gis/geos/libgeos.py:142:36: SyntaxError: def __init__(self, func_name, *, restype=None, errcheck=None, argtypes=None):\n.venv/lib/python3.8/site-packages/django/contrib/gis/geos/mutable_list.py:112:32: SyntaxError: return self.__class__([*self, *other])\n.venv/lib/python3.8/site-packages/django/contrib/gis/geos/polygon.py:34:19: SyntaxError: ext_ring, *init_holes = args\n.venv/lib/python3.8/site-packages/django/contrib/gis/geos/prototypes/coordseq.py:37:38: SyntaxError: def __init__(self, *args, ordinate=False, get=False, **kwargs):\n.venv/lib/python3.8/site-packages/django/contrib/gis/geos/prototypes/threadsafe.py:57:45: SyntaxError: self.cfunc.argtypes = [CONTEXT_PTR, *argtypes]\n.venv/lib/python3.8/site-packages/django/contrib/gis/management/commands/ogrinspect.py:112:31: SyntaxError: ogr_options = {k: v for k, v in options.items()\n.venv/lib/python3.8/site-packages/django/contrib/gis/measure.py:297:30: SyntaxError: LALIAS = {k.lower(): v for k, v in ALIAS.items()}\n.venv/lib/python3.8/site-packages/django/contrib/gis/serializers/geojson.py:16:37: SyntaxError: self.selected_fields = [*self.selected_fields, self.geometry_field]\n.venv/lib/python3.8/site-packages/django/contrib/gis/utils/layermapping.py:341:40: SyntaxError: return {fld: kwargs[fld] for fld in self.unique}\n.venv/lib/python3.8/site-packages/django/contrib/gis/utils/srs.py:63:33: SyntaxError: srs_field_names = {f.name for f in SpatialRefSys._meta.get_fields()}\n.venv/lib/python3.8/site-packages/django/contrib/messages/storage/cookie.py:42:23: SyntaxError: for key, value in obj.items()}\n.venv/lib/python3.8/site-packages/django/contrib/messages/utils.py:10:10: SyntaxError: **constants.DEFAULT_TAGS,\n.venv/lib/python3.8/site-packages/django/contrib/postgres/aggregates/mixins.py:6:45: SyntaxError: def __init__(self, *expressions, ordering=(), **extra):\n.venv/lib/python3.8/site-packages/django/contrib/postgres/constraints.py:13:16: SyntaxError: self, *, name, expressions, index_type=None, condition=None,\n.venv/lib/python3.8/site-packages/django/contrib/postgres/fields/array.py:30:40: SyntaxError: self.default_validators = [*self.default_validators, ArrayMaxLengthValidator(self.size)]\n.venv/lib/python3.8/site-packages/django/contrib/postgres/fields/hstore.py:51:14: SyntaxError: **kwargs,\n.venv/lib/python3.8/site-packages/django/contrib/postgres/forms/array.py:19:37: SyntaxError: def __init__(self, base_field, *, delimiter=',', max_length=None, min_length=None, **kwargs):\n.venv/lib/python3.8/site-packages/django/contrib/postgres/indexes.py:42:25: SyntaxError: def __init__(self, *, length=None, columns=(), **kwargs):\n.venv/lib/python3.8/site-packages/django/contrib/postgres/search.py:82:43: SyntaxError: def __init__(self, *expressions, config=None, weight=None):\n.venv/lib/python3.8/site-packages/django/contrib/postgres/serializers.py:10:69: SyntaxError: return '%s.%r' % (module, self.value), {'import %s' % module}\n.venv/lib/python3.8/site-packages/django/contrib/postgres/utils.py:25:22: SyntaxError: params={**error_params, **params},\n.venv/lib/python3.8/site-packages/django/contrib/postgres/validators.py:38:31: SyntaxError: self.messages = {**self.messages, **messages}\n.venv/lib/python3.8/site-packages/django/contrib/redirects/migrations/0001_initial.py:33:57: SyntaxError: 'unique_together': {('site', 'old_path')},\n.venv/lib/python3.8/site-packages/django/contrib/staticfiles/handlers.py:57:13: SyntaxError: async def get_response_async(self, request):\n.venv/lib/python3.8/site-packages/django/contrib/staticfiles/management/commands/collectstatic.py:87:60: SyntaxError: self.ignore_patterns = list({os.path.normpath(p) for p in ignore_patterns})\n.venv/lib/python3.8/site-packages/django/contrib/staticfiles/storage.py:234:38: SyntaxError: paths = {path: paths[path] for path in adjustable_paths}\n.venv/lib/python3.8/site-packages/django/contrib/staticfiles/utils.py:39:18: SyntaxError: yield from get_files(storage, ignore_patterns, dir)\n.venv/lib/python3.8/site-packages/django/core/cache/__init__.py:47:24: SyntaxError: params = {**conf, **kwargs}\n.venv/lib/python3.8/site-packages/django/core/cache/backends/memcached.py:90:63: SyntaxError: key_map = {self.make_key(key, version=version): key for key in keys}\n.venv/lib/python3.8/site-packages/django/core/checks/model_checks.py:108:24: SyntaxError: signal: name for name, signal in vars(signals).items()\n.venv/lib/python3.8/site-packages/django/core/checks/security/base.py:6:18: SyntaxError: 'no-referrer', 'no-referrer-when-downgrade', 'origin',\n.venv/lib/python3.8/site-packages/django/core/handlers/asgi.py:136:13: SyntaxError: async def __call__(self, scope, receive, send):\n.venv/lib/python3.8/site-packages/django/core/handlers/base.py:138:13: SyntaxError: async def get_response_async(self, request):\n.venv/lib/python3.8/site-packages/django/core/handlers/exception.py:36:13: SyntaxError: async def inner(request):\n.venv/lib/python3.8/site-packages/django/core/handlers/wsgi.py:139:13: SyntaxError: *response.items(),\n.venv/lib/python3.8/site-packages/django/core/mail/backends/filebased.py:14:39: SyntaxError: def __init__(self, *args, file_path=None, **kwargs):\n.venv/lib/python3.8/site-packages/django/core/mail/message.py:41:11: SyntaxError: 'from',\n.venv/lib/python3.8/site-packages/django/core/management/__init__.py:64:39: SyntaxError: commands = {name: 'django.core' for name in find_commands(__path__[0])}\n.venv/lib/python3.8/site-packages/django/core/management/base.py:29:40: SyntaxError: def __init__(self, *args, returncode=1, **kwargs):\n.venv/lib/python3.8/site-packages/django/core/management/commands/diffsettings.py:6:43: SyntaxError: return {k: repr(getattr(module, k)) for k in dir(module) if not omittable(k)}\n.venv/lib/python3.8/site-packages/django/core/management/commands/dumpdata.py:178:34: SyntaxError: yield from queryset.iterator()\n.venv/lib/python3.8/site-packages/django/core/management/commands/flush.py:74:22: SyntaxError: ) from exc\n.venv/lib/python3.8/site-packages/django/core/management/commands/inspectdb.py:62:25: SyntaxError: types = {'t'}\n.venv/lib/python3.8/site-packages/django/core/management/commands/loaddata.py:245:55: SyntaxError: targets = {'.'.join((fixture_name, suffix)) for suffix in suffixes}\n.venv/lib/python3.8/site-packages/django/core/management/commands/makemigrations.py:90:52: SyntaxError: consistency_check_labels = {config.label for config in apps.get_app_configs()}\n.venv/lib/python3.8/site-packages/django/core/management/commands/migrate.py:187:44: SyntaxError: (\", \".join(sorted({a for a, n in targets})) or \"(none)\")\n.venv/lib/python3.8/site-packages/django/core/management/templates.py:103:14: SyntaxError: **options,\n.venv/lib/python3.8/site-packages/django/core/management/utils.py:22:63: SyntaxError: raise CommandError('Error executing %s' % args[0]) from err\n.venv/lib/python3.8/site-packages/django/core/serializers/base.py:75:36: SyntaxError: def serialize(self, queryset, *, stream=None, fields=None, use_natural_foreign_keys=False,\n.venv/lib/python3.8/site-packages/django/core/serializers/json.py:70:18: SyntaxError: yield from PythonDeserializer(objects, **options)\n.venv/lib/python3.8/site-packages/django/core/serializers/python.py:78:32: SyntaxError: def Deserializer(object_list, *, using=DEFAULT_DB_ALIAS, ignorenonexistent=False, **options):\n.venv/lib/python3.8/site-packages/django/core/serializers/pyyaml.py:76:18: SyntaxError: yield from PythonDeserializer(yaml.load(stream, Loader=SafeLoader), **options)\n.venv/lib/python3.8/site-packages/django/core/serializers/xml_serializer.py:153:43: SyntaxError: def __init__(self, stream_or_string, *, using=DEFAULT_DB_ALIAS, ignorenonexistent=False, **options):\n.venv/lib/python3.8/site-packages/django/core/servers/basehttp.py:50:14: SyntaxError: ) from err\n.venv/lib/python3.8/site-packages/django/core/validators.py:411:28: SyntaxError: if exponent in {'F', 'n', 'N'}:\n.venv/lib/python3.8/site-packages/django/db/backends/base/base.py:618:33: SyntaxError: conn = self.__class__({**self.settings_dict, 'NAME': None}, alias=NO_DB_ALIAS)\n.venv/lib/python3.8/site-packages/django/db/backends/base/creation.py:67:23: SyntaxError: for app in apps.get_app_configs()\n.venv/lib/python3.8/site-packages/django/db/backends/base/introspection.py:110:17: SyntaxError: m for m in self.get_migratable_models()\n.venv/lib/python3.8/site-packages/django/db/backends/base/operations.py:247:54: SyntaxError: u_params = {to_string(k): to_string(v) for k, v in params.items()}\n.venv/lib/python3.8/site-packages/django/db/backends/base/schema.py:196:67: SyntaxError: 'definition': ', '.join(constraint for constraint in (*column_sqls, *constraints) if constraint),\n.venv/lib/python3.8/site-packages/django/db/backends/mysql/base.py:20:10: SyntaxError: ) from err\n.venv/lib/python3.8/site-packages/django/db/backends/mysql/creation.py:59:34: SyntaxError: dump_cmd = ['mysqldump', *dump_args[:-1], '--routines', '--events', source_database_name]\n.venv/lib/python3.8/site-packages/django/db/backends/mysql/features.py:140:26: SyntaxError: formats = {'JSON', 'TEXT', 'TRADITIONAL'}\n.venv/lib/python3.8/site-packages/django/db/backends/mysql/introspection.py:86:42: SyntaxError: json_constraints = {row[0] for row in cursor.fetchall()}\n.venv/lib/python3.8/site-packages/django/db/backends/mysql/operations.py:15:10: SyntaxError: **BaseDatabaseOperations.integer_field_ranges,\n.venv/lib/python3.8/site-packages/django/db/backends/mysql/validation.py:13:66: SyntaxError: if not (self.connection.sql_mode & {'STRICT_TRANS_TABLES', 'STRICT_ALL_TABLES'}):\n.venv/lib/python3.8/site-packages/django/db/backends/oracle/base.py:173:10: SyntaxError: **_standard_operators,\n.venv/lib/python3.8/site-packages/django/db/backends/oracle/client.py:16:35: SyntaxError: args = [wrapper_path, *args]\n.venv/lib/python3.8/site-packages/django/db/backends/oracle/creation.py:26:27: SyntaxError: settings_dict = {**settings_dict, 'USER': user, 'PASSWORD': password}\n.venv/lib/python3.8/site-packages/django/db/backends/oracle/functions.py:13:37: SyntaxError: def __init__(self, expression, *, output_field=None, **extra):\n.venv/lib/python3.8/site-packages/django/db/backends/oracle/introspection.py:123:15: SyntaxError: for column, default, internal_size, is_autofield, is_json in cursor.fetchall()\n.venv/lib/python3.8/site-packages/django/db/backends/oracle/operations.py:36:23: SyntaxError: set_operators = {**BaseDatabaseOperations.set_operators, 'difference': 'MINUS'}\n.venv/lib/python3.8/site-packages/django/db/backends/postgresql/base.py:172:14: SyntaxError: **settings_dict['OPTIONS'],\n.venv/lib/python3.8/site-packages/django/db/backends/postgresql/features.py:58:40: SyntaxError: supported_explain_formats = {'JSON', 'TEXT', 'XML', 'YAML'}\n.venv/lib/python3.8/site-packages/django/db/backends/postgresql/introspection.py:81:42: SyntaxError: field_map = {line[0]: line[1:] for line in cursor.fetchall()}\n.venv/lib/python3.8/site-packages/django/db/backends/postgresql/operations.py:120:41: SyntaxError: def sql_flush(self, style, tables, *, reset_sequences=False, allow_cascade=False):\n.venv/lib/python3.8/site-packages/django/db/backends/postgresql/schema.py:58:22: SyntaxError: yield from self._field_base_data_types(field.base_field)\n.venv/lib/python3.8/site-packages/django/db/backends/sqlite3/base.py:186:14: SyntaxError: **settings_dict['OPTIONS'],\n.venv/lib/python3.8/site-packages/django/db/backends/sqlite3/creation.py:58:22: SyntaxError: return {**orig_settings_dict, 'NAME': '{}_{}.{}'.format(root, suffix, ext)}\n.venv/lib/python3.8/site-packages/django/db/backends/sqlite3/introspection.py:62:63: SyntaxError: if description.pk and field_type in {'BigIntegerField', 'IntegerField', 'SmallIntegerField'}:\n.venv/lib/python3.8/site-packages/django/db/backends/sqlite3/operations.py:97:25: SyntaxError: field_name, *self._convert_tznames_to_sql(tzname),\n.venv/lib/python3.8/site-packages/django/db/backends/sqlite3/schema.py:164:15: SyntaxError: for f in model._meta.local_concrete_fields\n.venv/lib/python3.8/site-packages/django/db/backends/utils.py:30:22: SyntaxError: yield from self.cursor\n.venv/lib/python3.8/site-packages/django/db/migrations/autodetector.py:35:37: SyntaxError: self.existing_apps = {app for app, model in from_state.models}\n.venv/lib/python3.8/site-packages/django/db/migrations/executor.py:74:48: SyntaxError: self.loader.graph.nodes[key] for key in self.loader.applied_migrations\n.venv/lib/python3.8/site-packages/django/db/migrations/graph.py:137:18: SyntaxError: ) from err\n.venv/lib/python3.8/site-packages/django/db/migrations/loader.py:105:24: SyntaxError: name for _, name, is_pkg in pkgutil.iter_modules(module.__path__)\n.venv/lib/python3.8/site-packages/django/db/migrations/operations/fields.py:321:13: SyntaxError: for *_, field, reference in references:\n.venv/lib/python3.8/site-packages/django/db/migrations/operations/models.py:140:31: SyntaxError: options={**self.options, **operation.options},\n.venv/lib/python3.8/site-packages/django/db/migrations/recorder.py:78:66: SyntaxError: return {(migration.app, migration.name): migration for migration in self.migration_qs}\n.venv/lib/python3.8/site-packages/django/db/migrations/serializer.py:57:52: SyntaxError: return repr(self.value), {'import datetime'}\n.venv/lib/python3.8/site-packages/django/db/migrations/state.py:52:11: SyntaxError: for rel_mod in _get_related_models(model)\n.venv/lib/python3.8/site-packages/django/db/models/aggregates.py:24:45: SyntaxError: def __init__(self, *expressions, distinct=False, filter=None, **extra):\n.venv/lib/python3.8/site-packages/django/db/models/base.py:169:33: SyntaxError: field_names = {f.name for f in new_fields}\n.venv/lib/python3.8/site-packages/django/db/models/constraints.py:33:25: SyntaxError: def __init__(self, *, check, name):\n.venv/lib/python3.8/site-packages/django/db/models/deletion.py:148:19: SyntaxError: for field, items in self.restricted_objects[model].items()\n.venv/lib/python3.8/site-packages/django/db/models/enums.py:20:17: SyntaxError: *value, label = value\n.venv/lib/python3.8/site-packages/django/db/models/expressions.py:379:26: SyntaxError: yield from expr.flatten()\n.venv/lib/python3.8/site-packages/django/db/models/fields/__init__.py:199:13: SyntaxError: *self._check_field_name(),\n.venv/lib/python3.8/site-packages/django/db/models/fields/files.py:253:13: SyntaxError: *super().check(**kwargs),\n.venv/lib/python3.8/site-packages/django/db/models/fields/json.py:26:17: SyntaxError: **kwargs,\n.venv/lib/python3.8/site-packages/django/db/models/fields/related.py:100:13: SyntaxError: *super().check(**kwargs),\n.venv/lib/python3.8/site-packages/django/db/models/fields/related_descriptors.py:127:55: SyntaxError: instances_dict = {instance_attr(inst): inst for inst in instances}\n.venv/lib/python3.8/site-packages/django/db/models/functions/comparison.py:19:34: SyntaxError: if db_type in {'datetime', 'time'}:\n.venv/lib/python3.8/site-packages/django/db/models/functions/text.py:30:28: SyntaxError: **extra_content,\n.venv/lib/python3.8/site-packages/django/db/models/indexes.py:14:25: SyntaxError: def __init__(self, *, fields=(), name=None, db_tablespace=None, opclasses=(), condition=None):\n.venv/lib/python3.8/site-packages/django/db/models/manager.py:109:14: SyntaxError: **cls._get_queryset_methods(queryset_class),\n.venv/lib/python3.8/site-packages/django/db/models/options.py:65:17: SyntaxError: 'fields', 'many_to_many', 'concrete_fields', 'local_concrete_fields',\n.venv/lib/python3.8/site-packages/django/db/models/query.py:106:13: SyntaxError: *query.extra_select,\n.venv/lib/python3.8/site-packages/django/db/models/query_utils.py:47:40: SyntaxError: class InvalidQuery(Exception, metaclass=InvalidQueryType):\n.venv/lib/python3.8/site-packages/django/db/models/sql/compiler.py:118:27: SyntaxError: expr.source for expr in expressions if isinstance(expr, Ref)\n.venv/lib/python3.8/site-packages/django/db/models/sql/query.py:57:22: SyntaxError: yield from get_children_from_q(child)\n.venv/lib/python3.8/site-packages/django/db/models/sql/subqueries.py:140:46: SyntaxError: def __init__(self, *args, ignore_conflicts=False, **kwargs):\n.venv/lib/python3.8/site-packages/django/db/transaction.py:299:43: SyntaxError: view._non_atomic_requests = {using}\n.venv/lib/python3.8/site-packages/django/db/utils.py:90:65: SyntaxError: raise dj_exc_value.with_traceback(traceback) from exc_value\n.venv/lib/python3.8/site-packages/django/forms/boundfield.py:157:27: SyntaxError: attrs = {**(attrs or {}), 'for': id_for_label}\n.venv/lib/python3.8/site-packages/django/forms/fields.py:58:25: SyntaxError: def __init__(self, *, required=True, widget=None, label=None, initial=None,\n.venv/lib/python3.8/site-packages/django/forms/forms.py:493:31: SyntaxError: class Form(BaseForm, metaclass=DeclarativeFieldsMetaclass):\n.venv/lib/python3.8/site-packages/django/forms/models.py:109:43: SyntaxError: field_classes=None, *, apply_limit_choices_to=True):\n.venv/lib/python3.8/site-packages/django/forms/utils.py:52:34: SyntaxError: return {f: e.as_data() for f, e in self.items()}\n.venv/lib/python3.8/site-packages/django/forms/widgets.py:71:46: SyntaxError: return {medium: self.merge(*lists) for medium, lists in css.items()}\n.venv/lib/python3.8/site-packages/django/http/multipartparser.py:256:100: SyntaxError: raise MultiPartParserError(\"Could not decode base64 data.\") from exc\n.venv/lib/python3.8/site-packages/django/http/request.py:326:55: SyntaxError: raise UnreadablePostError(*e.args) from e\n.venv/lib/python3.8/site-packages/django/http/response.py:403:43: SyntaxError: def __init__(self, *args, as_attachment=False, filename='', **kwargs):\n.venv/lib/python3.8/site-packages/django/shortcuts.py:23:33: SyntaxError: def redirect(to, *args, permanent=False, **kwargs):\n.venv/lib/python3.8/site-packages/django/template/backends/django.py:84:18: SyntaxError: raise new from exc\n.venv/lib/python3.8/site-packages/django/template/backends/dummy.py:48:51: SyntaxError: context = {k: conditional_escape(v) for k, v in context.items()}\n.venv/lib/python3.8/site-packages/django/template/backends/jinja2.py:43:67: SyntaxError: raise TemplateDoesNotExist(exc.name, backend=self) from exc\n.venv/lib/python3.8/site-packages/django/template/base.py:159:22: SyntaxError: yield from node\n.venv/lib/python3.8/site-packages/django/template/context.py:188:18: SyntaxError: yield from self.dicts[-1]\n.venv/lib/python3.8/site-packages/django/template/defaulttags.py:294:22: SyntaxError: yield from nodelist\n.venv/lib/python3.8/site-packages/django/template/engine.py:110:21: SyntaxError: loader, *args = loader\n.venv/lib/python3.8/site-packages/django/template/library.py:180:52: SyntaxError: resolved_kwargs = {k: v.resolve(context) for k, v in self.kwargs.items()}\n.venv/lib/python3.8/site-packages/django/template/loader_tags.py:88:36: SyntaxError: self.blocks = {n.name: n for n in nodelist.get_nodes_by_type(BlockNode)}\n.venv/lib/python3.8/site-packages/django/template/loaders/cached.py:64:22: SyntaxError: yield from loader.get_template_sources(template_name)\n.venv/lib/python3.8/site-packages/django/template/utils.py:48:18: SyntaxError: **tpl,\n.venv/lib/python3.8/site-packages/django/templatetags/i18n.py:134:53: SyntaxError: context.update({var: val.resolve(context) for var, val in self.extra_context.items()})\n.venv/lib/python3.8/site-packages/django/test/client.py:89:18: SyntaxError: yield from iterable\n.venv/lib/python3.8/site-packages/django/test/html.py:79:33: SyntaxError: return hash((self.name, *self.attributes))\n.venv/lib/python3.8/site-packages/django/test/runner.py:466:19: SyntaxError: for pattern in test_name_patterns\n.venv/lib/python3.8/site-packages/django/test/selenium.py:98:53: SyntaxError: class SeleniumTestCase(LiveServerTestCase, metaclass=SeleniumTestCaseBase):\n.venv/lib/python3.8/site-packages/django/test/signals.py:23:41: SyntaxError: COMPLEX_OVERRIDE_SETTINGS = {'DATABASES'}\n.venv/lib/python3.8/site-packages/django/test/testcases.py:389:28: SyntaxError: **extra,\n.venv/lib/python3.8/site-packages/django/test/utils.py:123:31: SyntaxError: settings.ALLOWED_HOSTS = [*settings.ALLOWED_HOSTS, 'testserver']\n.venv/lib/python3.8/site-packages/django/urls/base.py:40:9: SyntaxError: *path, view = viewname.split(':')\n.venv/lib/python3.8/site-packages/django/urls/converters.py:62:14: SyntaxError: return {**DEFAULT_CONVERTERS, **REGISTERED_CONVERTERS}\n.venv/lib/python3.8/site-packages/django/urls/resolvers.py:163:30: SyntaxError: kwargs = {k: v for k, v in kwargs.items() if v is not None}\n.venv/lib/python3.8/site-packages/django/utils/autoreload.py:178:22: SyntaxError: yield from _walk(child, path + (prefix,))\n.venv/lib/python3.8/site-packages/django/utils/cache.py:98:31: SyntaxError: values = {True}\n.venv/lib/python3.8/site-packages/django/utils/crypto.py:19:48: SyntaxError: def salted_hmac(key_salt, value, secret=None, *, algorithm='sha1'):\n.venv/lib/python3.8/site-packages/django/utils/datastructures.py:102:18: SyntaxError: return {**self.__dict__, '_data': {k: self._getlist(k) for k in self}}\n.venv/lib/python3.8/site-packages/django/utils/dateparse.py:77:27: SyntaxError: kw = {k: int(v) for k, v in match.groupdict().items()}\n.venv/lib/python3.8/site-packages/django/utils/deconstruct.py:6:31: SyntaxError: def deconstructible(*args, path=None):\n.venv/lib/python3.8/site-packages/django/utils/deprecation.py:119:13: SyntaxError: async def __acall__(self, request):\n.venv/lib/python3.8/site-packages/django/utils/encoding.py:155:7: SyntaxError: for ascii_range in _ascii_ranges\n.venv/lib/python3.8/site-packages/django/utils/feedgenerator.py:81:14: SyntaxError: **kwargs,\n.venv/lib/python3.8/site-packages/django/utils/formats.py:255:37: SyntaxError: thousand_sep, unicodedata.normalize('NFKD', thousand_sep)}:\n.venv/lib/python3.8/site-packages/django/utils/html.py:114:47: SyntaxError: kwargs_safe = {k: conditional_escape(v) for (k, v) in kwargs.items()}\n.venv/lib/python3.8/site-packages/django/utils/http.py:196:62: SyntaxError: raise ValueError(\"%r is not a valid date\" % date) from exc\n.venv/lib/python3.8/site-packages/django/utils/log.py:201:41: SyntaxError: def log_response(message, *args, response=None, request=None, logger=request_logger, level=None, exc_info=None):\n.venv/lib/python3.8/site-packages/django/utils/module_loading.py:15:82: SyntaxError: raise ImportError(\"%s doesn't look like a module path\" % dotted_path) from err\n.venv/lib/python3.8/site-packages/django/utils/termcolors.py:6:43: SyntaxError: foreground = {color_names[x]: '3%s' % x for x in range(8)}\n.venv/lib/python3.8/site-packages/django/utils/topological_sort.py:17:27: SyntaxError: current = {node for node, deps in todo.items() if not deps}\n.venv/lib/python3.8/site-packages/django/utils/translation/__init__.py:298:48: SyntaxError: def get_supported_language_variant(lang_code, *, strict=False):\n.venv/lib/python3.8/site-packages/django/utils/translation/trans_real.py:86:22: SyntaxError: yield from cat.items()\n.venv/lib/python3.8/site-packages/django/utils/tree.py:76:68: SyntaxError: return hash((self.__class__, self.connector, self.negated, *make_hashable(self.children)))\n.venv/lib/python3.8/site-packages/django/views/debug.py:92:61: SyntaxError: cleansed = {k: self.cleanse_setting(k, v) for k, v in value.items()}\n.venv/lib/python3.8/site-packages/django/views/decorators/cache.py:8:26: SyntaxError: def cache_page(timeout, *, cache=None, key_prefix=None):\n.venv/lib/python3.8/site-packages/django/views/generic/list.py:113:33: SyntaxError: def get_context_data(self, *, object_list=None, **kwargs):\n.venv/lib/python3.8/site-packages/django/views/i18n.py:39:46: SyntaxError: allowed_hosts={request.get_host()},\n.venv/lib/python3.8/site-packages/html5lib/_trie/_base.py:16:21: SyntaxError: return {x for x in keys if x.startswith(prefix)}\n.venv/lib/python3.8/site-packages/httplib2/__init__.py:482:33: SyntaxError: print(\"%s:\" % h, end=\" \", file=self._fp)\n.venv/lib/python3.8/site-packages/jinja2/asyncfilters.py:8:9: SyntaxError: async def auto_to_seq(value):\n.venv/lib/python3.8/site-packages/jinja2/asyncsupport.py:18:9: SyntaxError: async def concat_async(async_gen):\n.venv/lib/python3.8/site-packages/jinja2/ext.py:177:20: SyntaxError: tags = {\"trans\"}\n.venv/lib/python3.8/site-packages/jinja2/filters.py:931:31: SyntaxError: if method not in {\"common\", \"ceil\", \"floor\"}:\n.venv/lib/python3.8/site-packages/jinja2/sandbox.py:27:23: SyntaxError: \"func_closure\",\n.venv/lib/python3.8/site-packages/jinja2/utils.py:701:40: SyntaxError: if name in {\"_Namespace__attrs\", \"__class__\"}:\n.venv/lib/python3.8/site-packages/magicmock/ClientAPI/__init__.py:149:15: SyntaxError: #SetDelay()\n.venv/lib/python3.8/site-packages/magicmock/Http/HttpController.py:21:4: SyntaxError: \n.venv/lib/python3.8/site-packages/magicmock/Http/web/python23.py:46:5: SyntaxError: \n.venv/lib/python3.8/site-packages/packaging/tags.py:555:54: SyntaxError: if self.e_ident_class not in {self.ELFCLASS32, self.ELFCLASS64}:\n.venv/lib/python3.8/site-packages/pep517/_in_process.py:242:35: SyntaxError: 'get_requires_for_build_wheel',\n.venv/lib/python3.8/site-packages/pep517/build.py:21:27: SyntaxError: required = {'requires', 'build-backend'}\n.venv/lib/python3.8/site-packages/pip/_internal/build_env.py:74:38: SyntaxError: os.path.normcase(site) for site in (\n.venv/lib/python3.8/site-packages/pip/_internal/cache.py:58:35: SyntaxError: _valid_formats = {\"source\", \"binary\"}\n.venv/lib/python3.8/site-packages/pip/_internal/cli/cmdoptions.py:107:48: SyntaxError: binary_only = FormatControl(set(), {':all:'})\n.venv/lib/python3.8/site-packages/pip/_internal/cli/parser.py:161:37: SyntaxError: section_items = {name: [] for name in override_order}\n.venv/lib/python3.8/site-packages/pip/_internal/commands/download.py:102:54: SyntaxError: with get_requirement_tracker() as req_tracker, TempDirectory(\n.venv/lib/python3.8/site-packages/pip/_internal/commands/freeze.py:15:18: SyntaxError: DEV_PKGS = {'pip', 'setuptools', 'distribute', 'wheel', 'pkg-resources'}\n.venv/lib/python3.8/site-packages/pip/_internal/commands/install.py:317:54: SyntaxError: with get_requirement_tracker() as req_tracker, TempDirectory(\n.venv/lib/python3.8/site-packages/pip/_internal/commands/list.py:182:23: SyntaxError: return {pkg for pkg in packages if pkg.key not in dep_keys}\n.venv/lib/python3.8/site-packages/pip/_internal/commands/wheel.py:128:54: SyntaxError: with get_requirement_tracker() as req_tracker, TempDirectory(\n.venv/lib/python3.8/site-packages/pip/_internal/configuration.py:139:27: SyntaxError: variant: [] for variant in self._override_order\n.venv/lib/python3.8/site-packages/pip/_internal/index/collector.py:98:29: SyntaxError: if scheme not in {'http', 'https'}:\n.venv/lib/python3.8/site-packages/pip/_internal/index/package_finder.py:460:22: SyntaxError: str(v) for v in specifier.filter(\n.venv/lib/python3.8/site-packages/pip/_internal/legacy_resolve.py:110:35: SyntaxError: _allowed_strategies = {\"eager\", \"only-if-needed\", \"to-satisfy-only\"}\n.venv/lib/python3.8/site-packages/pip/_internal/models/format_control.py:69:27: SyntaxError: result = {\"binary\", \"source\"}\n.venv/lib/python3.8/site-packages/pip/_internal/models/wheel.py:47:28: SyntaxError: Tag(x, y, z) for x in self.pyversions\n.venv/lib/python3.8/site-packages/pip/_internal/operations/install/legacy.py:69:26: SyntaxError: with indent_log(), install_req.build_env:\n.venv/lib/python3.8/site-packages/pip/_internal/operations/install/wheel.py:163:31: SyntaxError: parent_dir: scripts for parent_dir, scripts in grouped_by_dir.items()\n.venv/lib/python3.8/site-packages/pip/_internal/pep425tags.py:66:34: SyntaxError: if arch_suffix in {'i686', 'x86_64'}:\n.venv/lib/python3.8/site-packages/pip/_internal/req/req_install.py:146:51: SyntaxError: pkg_resources.safe_extra(extra) for extra in req.extras\n.venv/lib/python3.8/site-packages/pip/_internal/req/req_uninstall.py:203:37: SyntaxError: os.path.join(folder, \"*\") for folder in folders\n.venv/lib/python3.8/site-packages/pip/_internal/utils/compat.py:210:24: SyntaxError: stdlib_pkgs = {\"python\", \"wsgiref\", \"argparse\"}\n.venv/lib/python3.8/site-packages/pip/_internal/utils/misc.py:655:29: SyntaxError: reverse = {value: key for key, value in enums.items()}\n.venv/lib/python3.8/site-packages/pkg_resources/_vendor/pyparsing.py:24:1: SyntaxError: \n.venv/lib/python3.8/site-packages/pyparsing.py:6880:49: SyntaxError: name: getattr(__diag__, name) for name in __diag__._all_names\n.venv/lib/python3.8/site-packages/pytest/collect.py:24:24: SyntaxError: def __init__(self) -> None:\n.venv/lib/python3.8/site-packages/pytoml/__init__.py:1:28: SyntaxError: from .core import TomlError\n.venv/lib/python3.8/site-packages/pytoml/core.py:1:31: SyntaxError: class TomlError(RuntimeError):\n.venv/lib/python3.8/site-packages/pytoml/parser.py:1:15: SyntaxError: import re, sys\n.venv/lib/python3.8/site-packages/pytoml/test.py:1:16: SyntaxError: import datetime\n.venv/lib/python3.8/site-packages/pytoml/utils.py:1:16: SyntaxError: import datetime\n.venv/lib/python3.8/site-packages/pytoml/writer.py:1:40: SyntaxError: from __future__ import unicode_literals\n.venv/lib/python3.8/site-packages/requests/adapters.py:132:51: SyntaxError: return {attr: getattr(self, attr, None) for attr in self.__attrs__}\n.venv/lib/python3.8/site-packages/requests/hooks.py:18:25: SyntaxError: return {event: [] for event in HOOKS}\n.venv/lib/python3.8/site-packages/requests/models.py:655:51: SyntaxError: return {attr: getattr(self, attr, None) for attr in self.__attrs__}\n.venv/lib/python3.8/site-packages/requests/sessions.py:750:52: SyntaxError: state = {attr: getattr(self, attr, None) for attr in self.__attrs__}\n.venv/lib/python3.8/site-packages/setuptools/_imp.py:53:30: SyntaxError: if kind in {PY_SOURCE, PY_COMPILED}:\n.venv/lib/python3.8/site-packages/setuptools/_vendor/ordered_set.py:435:33: SyntaxError: self.map = {item: idx for (idx, item) in enumerate(items)}\n.venv/lib/python3.8/site-packages/setuptools/_vendor/pyparsing.py:24:1: SyntaxError: \n.venv/lib/python3.8/site-packages/setuptools/dist.py:448:20: SyntaxError: k: v for k, v in attrs.items()\n.venv/lib/python3.8/site-packages/setuptools/wheel.py:153:15: SyntaxError: for extra in dist.extras\n.venv/lib/python3.8/site-packages/sqlparse/filters/reindent.py:177:47: SyntaxError: with offset(self, adjusted_offset), indent(self):\n.venv/lib/python3.8/site-packages/sqlparse/sql.py:192:44: SyntaxError: .format(**locals()), file=f)\n.venv/lib/python3.8/site-packages/urllib3/connectionpool.py:100:33: SyntaxError: _blocking_errnos = {errno.EAGAIN, errno.EWOULDBLOCK}\n.venv/lib/python3.8/site-packages/urllib3/fields.py:75:11: SyntaxError: for cc in range(0x00, 0x1F + 1)\n.venv/lib/python3.8/site-packages/urllib3/packages/backports/makefile.py:20:29: SyntaxError: if not set(mode) <= {\"r\", \"w\", \"b\"}:\n.venv/lib/python3.8/site-packages/urllib3/request.py:39:36: SyntaxError: _encode_url_methods = {\"DELETE\", \"GET\", \"HEAD\", \"OPTIONS\"}\n.venv/lib/python3.8/site-packages/urllib3/util/url.py:77:59: SyntaxError: USERINFO_CHARS = UNRESERVED_CHARS | SUB_DELIM_CHARS | {\":\"}\n.venv/lib/python3.8/site-packages/wheel/bdist_wheel.py:329:22: SyntaxError: option for option in metadata.get('license_files', ('', ''))[1].split()\n.venv/lib/python3.8/site-packages/wheel/cli/pack.py:67:41: SyntaxError: impls = sorted({tag.split('-')[0] for tag in tags})\n.venv/lib/python3.8/site-packages/wheel/wheelfile.py:73:55: SyntaxError: if algorithm.lower() in {'md5', 'sha1'}:\n.venv/lib/python3.8/site-packages/yaml/__init__.py:399:27: SyntaxError: class YAMLObject(metaclass=YAMLObjectMetaclass):"
        }
    ], 
    "verified": false
}
