{
    "docs": "https://docs.ansible.com/ansible/2.10/dev_guide/testing/sanity/compile.html", 
    "results": [
        {
            "message": "The test `ansible-test sanity --test compile --python 2.7` [[explain](https://docs.ansible.com/ansible/2.10/dev_guide/testing/sanity/compile.html)] failed with 225 errors:", 
            "output": ".venv/lib/python3.8/site-packages/_pytest/_argcomplete.py:76:35: SyntaxError: def __init__(self, directories: bool = True) -> None:\n.venv/lib/python3.8/site-packages/_pytest/_code/code.py:58:33: SyntaxError: def __init__(self, rawcode) -> None:\n.venv/lib/python3.8/site-packages/_pytest/_code/source.py:23:27: SyntaxError: def __init__(self, obj: object = None) -> None:\n.venv/lib/python3.8/site-packages/_pytest/_io/saferepr.py:9:25: SyntaxError: def _try_repr_or_str(obj: object) -> str:\n.venv/lib/python3.8/site-packages/_pytest/_io/terminalwriter.py:16:26: SyntaxError: def get_terminal_width() -> int:\n.venv/lib/python3.8/site-packages/_pytest/_io/wcwidth.py:6:14: SyntaxError: def wcwidth(c: str) -> int:\n.venv/lib/python3.8/site-packages/_pytest/assertion/__init__.py:22:28: SyntaxError: def pytest_addoption(parser: Parser) -> None:\n.venv/lib/python3.8/site-packages/_pytest/assertion/rewrite.py:60:30: SyntaxError: def __init__(self, config: Config) -> None:\n.venv/lib/python3.8/site-packages/_pytest/assertion/truncate.py:19:16: SyntaxError: explanation: List[str], item: Item, max_length: Optional[int] = None\n.venv/lib/python3.8/site-packages/_pytest/assertion/util.py:32:35: SyntaxError: def format_explanation(explanation: str) -> str:\n.venv/lib/python3.8/site-packages/_pytest/cacheprovider.py:68:31: SyntaxError: def for_config(cls, config: Config) -> \"Cache\":\n.venv/lib/python3.8/site-packages/_pytest/capture.py:34:28: SyntaxError: def pytest_addoption(parser: Parser) -> None:\n.venv/lib/python3.8/site-packages/_pytest/compat.py:60:22: SyntaxError: def _format_args(func: Callable[..., Any]) -> str:\n.venv/lib/python3.8/site-packages/_pytest/config/__init__.py:106:13: SyntaxError: path: py.path.local,\n.venv/lib/python3.8/site-packages/_pytest/config/argparsing.py:42:14: SyntaxError: usage: Optional[str] = None,\n.venv/lib/python3.8/site-packages/_pytest/config/findpaths.py:23:27: SyntaxError: def _parse_ini_config(path: Path) -> iniconfig.IniConfig:\n.venv/lib/python3.8/site-packages/_pytest/debugging.py:33:31: SyntaxError: def _validate_usepdb_cls(value: str) -> Tuple[str, str]:\n.venv/lib/python3.8/site-packages/_pytest/doctest.py:65:28: SyntaxError: def pytest_addoption(parser: Parser) -> None:\n.venv/lib/python3.8/site-packages/_pytest/faulthandler.py:17:28: SyntaxError: def pytest_addoption(parser: Parser) -> None:\n.venv/lib/python3.8/site-packages/_pytest/fixtures.py:105:32: SyntaxError: def pytest_sessionstart(session: \"Session\") -> None:\n.venv/lib/python3.8/site-packages/_pytest/freeze_support.py:9:23: SyntaxError: def freeze_includes() -> List[str]:\n.venv/lib/python3.8/site-packages/_pytest/helpconfig.py:46:28: SyntaxError: def pytest_addoption(parser: Parser) -> None:\n.venv/lib/python3.8/site-packages/_pytest/hookspec.py:54:34: SyntaxError: def pytest_addhooks(pluginmanager: \"PytestPluginManager\") -> None:\n.venv/lib/python3.8/site-packages/_pytest/junitxml.py:40:23: SyntaxError: def bin_xml_escape(arg: object) -> str:\n.venv/lib/python3.8/site-packages/_pytest/logging.py:42:39: SyntaxError: def _remove_ansi_escape_sequences(text: str) -> str:\n.venv/lib/python3.8/site-packages/_pytest/main.py:51:28: SyntaxError: def pytest_addoption(parser: Parser) -> None:\n.venv/lib/python3.8/site-packages/_pytest/mark/__init__.py:48:12: SyntaxError: *values: object,\n.venv/lib/python3.8/site-packages/_pytest/mark/expression.py:65:30: SyntaxError: def __init__(self, column: int, message: str) -> None:\n.venv/lib/python3.8/site-packages/_pytest/mark/structures.py:41:22: SyntaxError: def istestfunc(func) -> bool:\n.venv/lib/python3.8/site-packages/_pytest/monkeypatch.py:30:19: SyntaxError: def monkeypatch() -> Generator[\"MonkeyPatch\", None, None]:\n.venv/lib/python3.8/site-packages/_pytest/nodes.py:53:22: SyntaxError: def _splitnode(nodeid: str) -> Tuple[str, ...]:\n.venv/lib/python3.8/site-packages/_pytest/nose.py:24:31: SyntaxError: def is_potential_nosetest(item: Item) -> bool:\n.venv/lib/python3.8/site-packages/_pytest/outcomes.py:29:27: SyntaxError: def __init__(self, msg: Optional[str] = None, pytrace: bool = True) -> None:\n.venv/lib/python3.8/site-packages/_pytest/pastebin.py:18:28: SyntaxError: def pytest_addoption(parser: Parser) -> None:\n.venv/lib/python3.8/site-packages/_pytest/pathlib.py:47:23: SyntaxError: def get_lock_path(path: _AnyPurePath) -> _AnyPurePath:\n.venv/lib/python3.8/site-packages/_pytest/pytester.py:63:28: SyntaxError: def pytest_addoption(parser: Parser) -> None:\n.venv/lib/python3.8/site-packages/_pytest/python.py:81:28: SyntaxError: def pytest_addoption(parser: Parser) -> None:\n.venv/lib/python3.8/site-packages/_pytest/python_api.py:30:38: SyntaxError: def _non_numeric_type_error(value, at: Optional[str]) -> TypeError:\n.venv/lib/python3.8/site-packages/_pytest/recwarn.py:30:15: SyntaxError: def recwarn() -> Generator[\"WarningsRecorder\", None, None]:\n.venv/lib/python3.8/site-packages/_pytest/reports.py:69:28: SyntaxError: def __init__(self, **kw: Any) -> None:\n.venv/lib/python3.8/site-packages/_pytest/runner.py:46:28: SyntaxError: def pytest_addoption(parser: Parser) -> None:\n.venv/lib/python3.8/site-packages/_pytest/setuponly.py:14:28: SyntaxError: def pytest_addoption(parser: Parser) -> None:\n.venv/lib/python3.8/site-packages/_pytest/setupplan.py:12:28: SyntaxError: def pytest_addoption(parser: Parser) -> None:\n.venv/lib/python3.8/site-packages/_pytest/skipping.py:29:28: SyntaxError: def pytest_addoption(parser: Parser) -> None:\n.venv/lib/python3.8/site-packages/_pytest/stepwise.py:12:28: SyntaxError: def pytest_addoption(parser: Parser) -> None:\n.venv/lib/python3.8/site-packages/_pytest/store.py:85:24: SyntaxError: def __init__(self) -> None:\n.venv/lib/python3.8/site-packages/_pytest/terminal.py:82:23: SyntaxError: option_strings: Sequence[str],\n.venv/lib/python3.8/site-packages/_pytest/tmpdir.py:44:32: SyntaxError: def from_config(cls, config: Config) -> \"TempPathFactory\":\n.venv/lib/python3.8/site-packages/_pytest/unittest.py:47:14: SyntaxError: collector: PyCollector, name: str, obj: object\n.venv/lib/python3.8/site-packages/_pytest/warning_types.py:66:28: SyntaxError: def simple(cls, apiname: str) -> \"PytestExperimentalApiWarning\":\n.venv/lib/python3.8/site-packages/_pytest/warnings.py:20:28: SyntaxError: def pytest_configure(config: Config) -> None:\n.venv/lib/python3.8/site-packages/ansible_collections/netbox/netbox/docs/conf.py:87:140: SyntaxError: args_string = f\"junk plugin --dest-dir plugins/{plugin_type}/{file_name}/ --plugin-type {plugin_type} netbox.netbox.{file_name}\"\n.venv/lib/python3.8/site-packages/ansible_collections/netbox/netbox/tests/test_data.py:14:55: SyntaxError: with open(f\"{path}/test_data/{test_path}/data.json\", \"r\") as f:\n.venv/lib/python3.8/site-packages/asgiref/compatibility.py:32:13: SyntaxError: async def new_application(scope, receive, send):\n.venv/lib/python3.8/site-packages/asgiref/server.py:66:13: SyntaxError: async def handle(self):\n.venv/lib/python3.8/site-packages/asgiref/sync.py:191:13: SyntaxError: async def main_wrap(\n.venv/lib/python3.8/site-packages/asgiref/testing.py:23:13: SyntaxError: async def wait(self, timeout=1):\n.venv/lib/python3.8/site-packages/asgiref/timeout.py:34:16: SyntaxError: timeout: Optional[float],\n.venv/lib/python3.8/site-packages/asgiref/wsgi.py:15:13: SyntaxError: async def __call__(self, scope, receive, send):\n.venv/lib/python3.8/site-packages/attr/_next_gen.py:18:6: SyntaxError: *,\n.venv/lib/python3.8/site-packages/cs/_async.py:16:13: SyntaxError: async def _request(self, command, json=True, opcode_name='command',\n.venv/lib/python3.8/site-packages/django/apps/registry.py:397:25: SyntaxError: next_model, *more_models = model_keys\n.venv/lib/python3.8/site-packages/django/conf/__init__.py:267:25: SyntaxError: s for s in [*self.__dict__, *dir(self.default_settings)]\n.venv/lib/python3.8/site-packages/django/conf/urls/i18n.py:8:48: SyntaxError: def i18n_patterns(*urls, prefix_default_language=True):\n.venv/lib/python3.8/site-packages/django/contrib/admin/actions.py:55:10: SyntaxError: **modeladmin.admin_site.each_context(request),\n.venv/lib/python3.8/site-packages/django/contrib/admin/checks.py:144:13: SyntaxError: *self._check_autocomplete_fields(admin_obj),\n.venv/lib/python3.8/site-packages/django/contrib/admin/decorators.py:1:26: SyntaxError: def register(*models, site=None):\n.venv/lib/python3.8/site-packages/django/contrib/admin/forms.py:11:10: SyntaxError: **AuthenticationForm.error_messages,\n.venv/lib/python3.8/site-packages/django/contrib/admin/options.py:98:31: SyntaxError: class BaseModelAdmin(metaclass=forms.MediaDefiningClass):\n.venv/lib/python3.8/site-packages/django/contrib/admin/sites.py:327:32: SyntaxError: 'extra_context': {**self.each_context(request), **(extra_context or {})},\n.venv/lib/python3.8/site-packages/django/contrib/admin/templatetags/admin_list.py:72:21: SyntaxError: *range(0, ON_ENDS), DOT,\n.venv/lib/python3.8/site-packages/django/contrib/admin/views/main.py:180:59: SyntaxError: raise IncorrectLookupParameters(e) from e\n.venv/lib/python3.8/site-packages/django/contrib/admin/widgets.py:57:56: SyntaxError: attrs = {'class': 'vDateField', 'size': '10', **(attrs or {})}\n.venv/lib/python3.8/site-packages/django/contrib/admindocs/views.py:47:14: SyntaxError: **kwargs,\n.venv/lib/python3.8/site-packages/django/contrib/auth/admin.py:179:14: SyntaxError: **self.admin_site.each_context(request),\n.venv/lib/python3.8/site-packages/django/contrib/auth/backends.py:23:13: SyntaxError: *self.get_user_permissions(user_obj, obj=obj),\n.venv/lib/python3.8/site-packages/django/contrib/auth/forms.py:76:14: SyntaxError: **super().widget_attrs(widget),\n.venv/lib/python3.8/site-packages/django/contrib/auth/management/__init__.py:18:13: SyntaxError: return [*_get_builtin_permissions(opts), *opts.permissions]\n.venv/lib/python3.8/site-packages/django/contrib/auth/views.py:37:42: SyntaxError: return {self.request.get_host(), *self.success_url_allowed_hosts}\n.venv/lib/python3.8/site-packages/django/contrib/contenttypes/admin.py:95:20: SyntaxError: exclude = [*(self.exclude or []), *self.get_readonly_fields(request, obj)]\n.venv/lib/python3.8/site-packages/django/contrib/contenttypes/fields.py:78:13: SyntaxError: *self._check_field_name(),\n.venv/lib/python3.8/site-packages/django/contrib/contenttypes/forms.py:72:16: SyntaxError: exclude = [*(exclude or []), ct_field.name, fk_field.name]\n.venv/lib/python3.8/site-packages/django/contrib/contenttypes/models.py:62:57: SyntaxError: def get_for_models(self, *models, for_concrete_models=True):\n.venv/lib/python3.8/site-packages/django/contrib/gis/db/backends/oracle/introspection.py:14:14: SyntaxError: **super().data_types_reverse,\n.venv/lib/python3.8/site-packages/django/contrib/gis/db/backends/spatialite/introspection.py:13:10: SyntaxError: **FlexibleFieldLookupDict.base_data_types_reverse,\n.venv/lib/python3.8/site-packages/django/contrib/gis/db/backends/spatialite/operations.py:99:18: SyntaxError: ) from exc\n.venv/lib/python3.8/site-packages/django/contrib/gis/db/models/aggregates.py:34:17: SyntaxError: *self.get_source_expressions(),\n.venv/lib/python3.8/site-packages/django/contrib/gis/db/models/fields.py:207:68: SyntaxError: def __init__(self, verbose_name=None, dim=2, geography=False, *, extent=(-180.0, -90.0, 180.0, 90.0),\n.venv/lib/python3.8/site-packages/django/contrib/gis/db/models/functions.py:120:39: SyntaxError: clone.set_source_expressions([*self.get_source_expressions(), tolerance])\n.venv/lib/python3.8/site-packages/django/contrib/gis/db/models/lookups.py:22:14: SyntaxError: rhs, *self.rhs_params = rhs if isinstance(rhs, (list, tuple)) else [rhs]\n.venv/lib/python3.8/site-packages/django/contrib/gis/forms/fields.py:27:25: SyntaxError: def __init__(self, *, srid=None, geom_type=None, **kwargs):\n.venv/lib/python3.8/site-packages/django/contrib/gis/forms/widgets.py:71:14: SyntaxError: **(attrs or {}),\n.venv/lib/python3.8/site-packages/django/contrib/gis/geos/libgeos.py:142:36: SyntaxError: def __init__(self, func_name, *, restype=None, errcheck=None, argtypes=None):\n.venv/lib/python3.8/site-packages/django/contrib/gis/geos/mutable_list.py:112:32: SyntaxError: return self.__class__([*self, *other])\n.venv/lib/python3.8/site-packages/django/contrib/gis/geos/polygon.py:34:19: SyntaxError: ext_ring, *init_holes = args\n.venv/lib/python3.8/site-packages/django/contrib/gis/geos/prototypes/coordseq.py:37:38: SyntaxError: def __init__(self, *args, ordinate=False, get=False, **kwargs):\n.venv/lib/python3.8/site-packages/django/contrib/gis/geos/prototypes/threadsafe.py:57:45: SyntaxError: self.cfunc.argtypes = [CONTEXT_PTR, *argtypes]\n.venv/lib/python3.8/site-packages/django/contrib/gis/serializers/geojson.py:16:37: SyntaxError: self.selected_fields = [*self.selected_fields, self.geometry_field]\n.venv/lib/python3.8/site-packages/django/contrib/gis/utils/layermapping.py:464:18: SyntaxError: ) from exc\n.venv/lib/python3.8/site-packages/django/contrib/messages/utils.py:10:10: SyntaxError: **constants.DEFAULT_TAGS,\n.venv/lib/python3.8/site-packages/django/contrib/postgres/aggregates/mixins.py:6:45: SyntaxError: def __init__(self, *expressions, ordering=(), **extra):\n.venv/lib/python3.8/site-packages/django/contrib/postgres/constraints.py:13:16: SyntaxError: self, *, name, expressions, index_type=None, condition=None,\n.venv/lib/python3.8/site-packages/django/contrib/postgres/fields/array.py:30:40: SyntaxError: self.default_validators = [*self.default_validators, ArrayMaxLengthValidator(self.size)]\n.venv/lib/python3.8/site-packages/django/contrib/postgres/fields/hstore.py:51:14: SyntaxError: **kwargs,\n.venv/lib/python3.8/site-packages/django/contrib/postgres/forms/array.py:19:37: SyntaxError: def __init__(self, base_field, *, delimiter=',', max_length=None, min_length=None, **kwargs):\n.venv/lib/python3.8/site-packages/django/contrib/postgres/indexes.py:42:25: SyntaxError: def __init__(self, *, length=None, columns=(), **kwargs):\n.venv/lib/python3.8/site-packages/django/contrib/postgres/search.py:82:43: SyntaxError: def __init__(self, *expressions, config=None, weight=None):\n.venv/lib/python3.8/site-packages/django/contrib/postgres/utils.py:25:22: SyntaxError: params={**error_params, **params},\n.venv/lib/python3.8/site-packages/django/contrib/postgres/validators.py:38:31: SyntaxError: self.messages = {**self.messages, **messages}\n.venv/lib/python3.8/site-packages/django/contrib/staticfiles/handlers.py:57:13: SyntaxError: async def get_response_async(self, request):\n.venv/lib/python3.8/site-packages/django/contrib/staticfiles/storage.py:399:18: SyntaxError: yield from super().post_process(*args, **kwargs)\n.venv/lib/python3.8/site-packages/django/contrib/staticfiles/utils.py:39:18: SyntaxError: yield from get_files(storage, ignore_patterns, dir)\n.venv/lib/python3.8/site-packages/django/core/cache/__init__.py:47:24: SyntaxError: params = {**conf, **kwargs}\n.venv/lib/python3.8/site-packages/django/core/handlers/asgi.py:136:13: SyntaxError: async def __call__(self, scope, receive, send):\n.venv/lib/python3.8/site-packages/django/core/handlers/base.py:138:13: SyntaxError: async def get_response_async(self, request):\n.venv/lib/python3.8/site-packages/django/core/handlers/exception.py:36:13: SyntaxError: async def inner(request):\n.venv/lib/python3.8/site-packages/django/core/handlers/wsgi.py:139:13: SyntaxError: *response.items(),\n.venv/lib/python3.8/site-packages/django/core/mail/backends/filebased.py:14:39: SyntaxError: def __init__(self, *args, file_path=None, **kwargs):\n.venv/lib/python3.8/site-packages/django/core/management/__init__.py:128:30: SyntaxError: yield from get_actions(sub_opt)\n.venv/lib/python3.8/site-packages/django/core/management/base.py:29:40: SyntaxError: def __init__(self, *args, returncode=1, **kwargs):\n.venv/lib/python3.8/site-packages/django/core/management/commands/dumpdata.py:178:34: SyntaxError: yield from queryset.iterator()\n.venv/lib/python3.8/site-packages/django/core/management/commands/flush.py:74:22: SyntaxError: ) from exc\n.venv/lib/python3.8/site-packages/django/core/management/commands/inspectdb.py:173:26: SyntaxError: yield from self.get_meta(table_name, constraints, column_to_field_name, is_view, is_partition)\n.venv/lib/python3.8/site-packages/django/core/management/templates.py:103:14: SyntaxError: **options,\n.venv/lib/python3.8/site-packages/django/core/management/utils.py:22:63: SyntaxError: raise CommandError('Error executing %s' % args[0]) from err\n.venv/lib/python3.8/site-packages/django/core/serializers/base.py:75:36: SyntaxError: def serialize(self, queryset, *, stream=None, fields=None, use_natural_foreign_keys=False,\n.venv/lib/python3.8/site-packages/django/core/serializers/json.py:70:18: SyntaxError: yield from PythonDeserializer(objects, **options)\n.venv/lib/python3.8/site-packages/django/core/serializers/python.py:78:32: SyntaxError: def Deserializer(object_list, *, using=DEFAULT_DB_ALIAS, ignorenonexistent=False, **options):\n.venv/lib/python3.8/site-packages/django/core/serializers/pyyaml.py:76:18: SyntaxError: yield from PythonDeserializer(yaml.load(stream, Loader=SafeLoader), **options)\n.venv/lib/python3.8/site-packages/django/core/serializers/xml_serializer.py:153:43: SyntaxError: def __init__(self, stream_or_string, *, using=DEFAULT_DB_ALIAS, ignorenonexistent=False, **options):\n.venv/lib/python3.8/site-packages/django/core/servers/basehttp.py:50:14: SyntaxError: ) from err\n.venv/lib/python3.8/site-packages/django/db/backends/base/base.py:618:33: SyntaxError: conn = self.__class__({**self.settings_dict, 'NAME': None}, alias=NO_DB_ALIAS)\n.venv/lib/python3.8/site-packages/django/db/backends/base/creation.py:128:38: SyntaxError: yield from queryset.iterator()\n.venv/lib/python3.8/site-packages/django/db/backends/base/operations.py:385:41: SyntaxError: def sql_flush(self, style, tables, *, reset_sequences=False, allow_cascade=False):\n.venv/lib/python3.8/site-packages/django/db/backends/base/schema.py:196:67: SyntaxError: 'definition': ', '.join(constraint for constraint in (*column_sqls, *constraints) if constraint),\n.venv/lib/python3.8/site-packages/django/db/backends/mysql/base.py:20:10: SyntaxError: ) from err\n.venv/lib/python3.8/site-packages/django/db/backends/mysql/creation.py:59:34: SyntaxError: dump_cmd = ['mysqldump', *dump_args[:-1], '--routines', '--events', source_database_name]\n.venv/lib/python3.8/site-packages/django/db/backends/mysql/introspection.py:122:13: SyntaxError: ))\n.venv/lib/python3.8/site-packages/django/db/backends/mysql/operations.py:15:10: SyntaxError: **BaseDatabaseOperations.integer_field_ranges,\n.venv/lib/python3.8/site-packages/django/db/backends/oracle/base.py:173:10: SyntaxError: **_standard_operators,\n.venv/lib/python3.8/site-packages/django/db/backends/oracle/client.py:16:35: SyntaxError: args = [wrapper_path, *args]\n.venv/lib/python3.8/site-packages/django/db/backends/oracle/creation.py:26:27: SyntaxError: settings_dict = {**settings_dict, 'USER': user, 'PASSWORD': password}\n.venv/lib/python3.8/site-packages/django/db/backends/oracle/functions.py:13:37: SyntaxError: def __init__(self, expression, *, output_field=None, **extra):\n.venv/lib/python3.8/site-packages/django/db/backends/oracle/introspection.py:136:31: SyntaxError: desc[5] or 0, *desc[6:], default, is_autofield, is_json,\n.venv/lib/python3.8/site-packages/django/db/backends/oracle/operations.py:36:23: SyntaxError: set_operators = {**BaseDatabaseOperations.set_operators, 'difference': 'MINUS'}\n.venv/lib/python3.8/site-packages/django/db/backends/postgresql/base.py:172:14: SyntaxError: **settings_dict['OPTIONS'],\n.venv/lib/python3.8/site-packages/django/db/backends/postgresql/introspection.py:92:13: SyntaxError: )\n.venv/lib/python3.8/site-packages/django/db/backends/postgresql/operations.py:120:41: SyntaxError: def sql_flush(self, style, tables, *, reset_sequences=False, allow_cascade=False):\n.venv/lib/python3.8/site-packages/django/db/backends/postgresql/schema.py:58:22: SyntaxError: yield from self._field_base_data_types(field.base_field)\n.venv/lib/python3.8/site-packages/django/db/backends/sqlite3/base.py:186:14: SyntaxError: **settings_dict['OPTIONS'],\n.venv/lib/python3.8/site-packages/django/db/backends/sqlite3/creation.py:58:22: SyntaxError: return {**orig_settings_dict, 'NAME': '{}_{}.{}'.format(root, suffix, ext)}\n.venv/lib/python3.8/site-packages/django/db/backends/sqlite3/operations.py:97:25: SyntaxError: field_name, *self._convert_tznames_to_sql(tzname),\n.venv/lib/python3.8/site-packages/django/db/backends/utils.py:30:22: SyntaxError: yield from self.cursor\n.venv/lib/python3.8/site-packages/django/db/migrations/graph.py:137:18: SyntaxError: ) from err\n.venv/lib/python3.8/site-packages/django/db/migrations/loader.py:118:30: SyntaxError: ) from e\n.venv/lib/python3.8/site-packages/django/db/migrations/operations/fields.py:321:13: SyntaxError: for *_, field, reference in references:\n.venv/lib/python3.8/site-packages/django/db/migrations/operations/models.py:140:31: SyntaxError: options={**self.options, **operation.options},\n.venv/lib/python3.8/site-packages/django/db/migrations/serializer.py:170:40: SyntaxError: imports = {'import functools', *func_imports, *args_imports, *keywords_imports}\n.venv/lib/python3.8/site-packages/django/db/migrations/state.py:262:66: SyntaxError: app_configs = [AppConfigStub(label) for label in sorted([*real_apps, *app_labels])]\n.venv/lib/python3.8/site-packages/django/db/models/aggregates.py:24:45: SyntaxError: def __init__(self, *expressions, distinct=False, filter=None, **extra):\n.venv/lib/python3.8/site-packages/django/db/models/base.py:404:22: SyntaxError: class Model(metaclass=ModelBase):\n.venv/lib/python3.8/site-packages/django/db/models/constraints.py:33:25: SyntaxError: def __init__(self, *, check, name):\n.venv/lib/python3.8/site-packages/django/db/models/enums.py:20:17: SyntaxError: *value, label = value\n.venv/lib/python3.8/site-packages/django/db/models/expressions.py:379:26: SyntaxError: yield from expr.flatten()\n.venv/lib/python3.8/site-packages/django/db/models/fields/__init__.py:199:13: SyntaxError: *self._check_field_name(),\n.venv/lib/python3.8/site-packages/django/db/models/fields/files.py:253:13: SyntaxError: *super().check(**kwargs),\n.venv/lib/python3.8/site-packages/django/db/models/fields/json.py:26:17: SyntaxError: **kwargs,\n.venv/lib/python3.8/site-packages/django/db/models/fields/related.py:100:13: SyntaxError: *super().check(**kwargs),\n.venv/lib/python3.8/site-packages/django/db/models/fields/related_descriptors.py:569:29: SyntaxError: def __call__(self, *, manager):\n.venv/lib/python3.8/site-packages/django/db/models/functions/text.py:30:28: SyntaxError: **extra_content,\n.venv/lib/python3.8/site-packages/django/db/models/indexes.py:14:25: SyntaxError: def __init__(self, *, fields=(), name=None, db_tablespace=None, opclasses=(), condition=None):\n.venv/lib/python3.8/site-packages/django/db/models/manager.py:109:14: SyntaxError: **cls._get_queryset_methods(queryset_class),\n.venv/lib/python3.8/site-packages/django/db/models/query.py:106:13: SyntaxError: *query.extra_select,\n.venv/lib/python3.8/site-packages/django/db/models/query_utils.py:47:40: SyntaxError: class InvalidQuery(Exception, metaclass=InvalidQueryType):\n.venv/lib/python3.8/site-packages/django/db/models/sql/compiler.py:454:25: SyntaxError: *self.query.extra_select,\n.venv/lib/python3.8/site-packages/django/db/models/sql/query.py:57:22: SyntaxError: yield from get_children_from_q(child)\n.venv/lib/python3.8/site-packages/django/db/models/sql/subqueries.py:140:46: SyntaxError: def __init__(self, *args, ignore_conflicts=False, **kwargs):\n.venv/lib/python3.8/site-packages/django/db/utils.py:90:65: SyntaxError: raise dj_exc_value.with_traceback(traceback) from exc_value\n.venv/lib/python3.8/site-packages/django/forms/boundfield.py:157:27: SyntaxError: attrs = {**(attrs or {}), 'for': id_for_label}\n.venv/lib/python3.8/site-packages/django/forms/fields.py:58:25: SyntaxError: def __init__(self, *, required=True, widget=None, label=None, initial=None,\n.venv/lib/python3.8/site-packages/django/forms/forms.py:493:31: SyntaxError: class Form(BaseForm, metaclass=DeclarativeFieldsMetaclass):\n.venv/lib/python3.8/site-packages/django/forms/models.py:109:43: SyntaxError: field_classes=None, *, apply_limit_choices_to=True):\n.venv/lib/python3.8/site-packages/django/forms/utils.py:172:18: SyntaxError: ) from exc\n.venv/lib/python3.8/site-packages/django/forms/widgets.py:194:23: SyntaxError: class Widget(metaclass=MediaDefiningClass):\n.venv/lib/python3.8/site-packages/django/http/multipartparser.py:256:100: SyntaxError: raise MultiPartParserError(\"Could not decode base64 data.\") from exc\n.venv/lib/python3.8/site-packages/django/http/request.py:326:55: SyntaxError: raise UnreadablePostError(*e.args) from e\n.venv/lib/python3.8/site-packages/django/http/response.py:403:43: SyntaxError: def __init__(self, *args, as_attachment=False, filename='', **kwargs):\n.venv/lib/python3.8/site-packages/django/shortcuts.py:23:33: SyntaxError: def redirect(to, *args, permanent=False, **kwargs):\n.venv/lib/python3.8/site-packages/django/template/backends/django.py:84:18: SyntaxError: raise new from exc\n.venv/lib/python3.8/site-packages/django/template/backends/jinja2.py:43:67: SyntaxError: raise TemplateDoesNotExist(exc.name, backend=self) from exc\n.venv/lib/python3.8/site-packages/django/template/base.py:159:22: SyntaxError: yield from node\n.venv/lib/python3.8/site-packages/django/template/context.py:188:18: SyntaxError: yield from self.dicts[-1]\n.venv/lib/python3.8/site-packages/django/template/defaulttags.py:294:22: SyntaxError: yield from nodelist\n.venv/lib/python3.8/site-packages/django/template/engine.py:110:21: SyntaxError: loader, *args = loader\n.venv/lib/python3.8/site-packages/django/template/loader_tags.py:156:53: SyntaxError: def __init__(self, template, *args, extra_context=None, isolated_context=False, **kwargs):\n.venv/lib/python3.8/site-packages/django/template/loaders/cached.py:64:22: SyntaxError: yield from loader.get_template_sources(template_name)\n.venv/lib/python3.8/site-packages/django/template/utils.py:48:18: SyntaxError: **tpl,\n.venv/lib/python3.8/site-packages/django/test/client.py:89:18: SyntaxError: yield from iterable\n.venv/lib/python3.8/site-packages/django/test/html.py:79:33: SyntaxError: return hash((self.name, *self.attributes))\n.venv/lib/python3.8/site-packages/django/test/selenium.py:98:53: SyntaxError: class SeleniumTestCase(LiveServerTestCase, metaclass=SeleniumTestCaseBase):\n.venv/lib/python3.8/site-packages/django/test/testcases.py:389:28: SyntaxError: **extra,\n.venv/lib/python3.8/site-packages/django/test/utils.py:123:31: SyntaxError: settings.ALLOWED_HOSTS = [*settings.ALLOWED_HOSTS, 'testserver']\n.venv/lib/python3.8/site-packages/django/urls/base.py:40:9: SyntaxError: *path, view = viewname.split(':')\n.venv/lib/python3.8/site-packages/django/urls/converters.py:62:14: SyntaxError: return {**DEFAULT_CONVERTERS, **REGISTERED_CONVERTERS}\n.venv/lib/python3.8/site-packages/django/urls/resolvers.py:193:18: SyntaxError: ) from e\n.venv/lib/python3.8/site-packages/django/utils/autoreload.py:178:22: SyntaxError: yield from _walk(child, path + (prefix,))\n.venv/lib/python3.8/site-packages/django/utils/crypto.py:19:48: SyntaxError: def salted_hmac(key_salt, value, secret=None, *, algorithm='sha1'):\n.venv/lib/python3.8/site-packages/django/utils/datastructures.py:102:18: SyntaxError: return {**self.__dict__, '_data': {k: self._getlist(k) for k in self}}\n.venv/lib/python3.8/site-packages/django/utils/deconstruct.py:6:31: SyntaxError: def deconstructible(*args, path=None):\n.venv/lib/python3.8/site-packages/django/utils/deprecation.py:119:13: SyntaxError: async def __acall__(self, request):\n.venv/lib/python3.8/site-packages/django/utils/feedgenerator.py:81:14: SyntaxError: **kwargs,\n.venv/lib/python3.8/site-packages/django/utils/http.py:196:62: SyntaxError: raise ValueError(\"%r is not a valid date\" % date) from exc\n.venv/lib/python3.8/site-packages/django/utils/log.py:201:41: SyntaxError: def log_response(message, *args, response=None, request=None, logger=request_logger, level=None, exc_info=None):\n.venv/lib/python3.8/site-packages/django/utils/module_loading.py:15:82: SyntaxError: raise ImportError(\"%s doesn't look like a module path\" % dotted_path) from err\n.venv/lib/python3.8/site-packages/django/utils/translation/__init__.py:298:48: SyntaxError: def get_supported_language_variant(lang_code, *, strict=False):\n.venv/lib/python3.8/site-packages/django/utils/translation/trans_real.py:86:22: SyntaxError: yield from cat.items()\n.venv/lib/python3.8/site-packages/django/utils/tree.py:76:68: SyntaxError: return hash((self.__class__, self.connector, self.negated, *make_hashable(self.children)))\n.venv/lib/python3.8/site-packages/django/views/decorators/cache.py:8:26: SyntaxError: def cache_page(timeout, *, cache=None, key_prefix=None):\n.venv/lib/python3.8/site-packages/django/views/generic/list.py:113:33: SyntaxError: def get_context_data(self, *, object_list=None, **kwargs):\n.venv/lib/python3.8/site-packages/httplib2/__init__.py:482:33: SyntaxError: print(\"%s:\" % h, end=\" \", file=self._fp)\n.venv/lib/python3.8/site-packages/jinja2/asyncfilters.py:8:9: SyntaxError: async def auto_to_seq(value):\n.venv/lib/python3.8/site-packages/jinja2/asyncsupport.py:18:9: SyntaxError: async def concat_async(async_gen):\n.venv/lib/python3.8/site-packages/pytest/collect.py:24:24: SyntaxError: def __init__(self) -> None:\n.venv/lib/python3.8/site-packages/sqlparse/sql.py:192:44: SyntaxError: .format(**locals()), file=f)\n.venv/lib/python3.8/site-packages/yaml/__init__.py:399:27: SyntaxError: class YAMLObject(metaclass=YAMLObjectMetaclass):"
        }
    ], 
    "verified": false
}
